<?xml version='1.0'?>

<robot name="tryrobot" xmlns:xacro="http://www.ros.org/wiki/xacro">

  <xacro:include filename="$(find trybot_description)/urdf/trybot.gazebo" />

  <!-- ******************* WORLD LINK ******************* -->
  <link name="world" />

  <!-- ********************* AXIS-1 ********************* -->
  <link name="axis1">
  	<visual>
	  <origin xyz="0 0 0.5" rpy="0 0 0" />
  	  <geometry>
				<!--<box size="1.0 1.0 -0.1"/>-->
        <box size="0.1 0.1 1.0"/>
  	  </geometry>
			<material name="yellow">
  		<color rgba="1 1 0 1" />
  	  </material>
  	</visual>

	<inertial>
	  <mass value="0.1405"/>
	  <inertia
		  ixx="0.011825416666666668" ixy="0.0" ixz="0.0"
		  iyy="0.00023416666666666673" iyz="0.0"
		  izz="0.011825416666666668"/>
	</inertial>

	<collision>
	  <origin xyz="0 0 0.5" rpy="0 0 0" />
	  <geometry>
      <box size="0.1 0.1 1.0"/>
	  </geometry>
	</collision>
  </link>

  <!-- ********************* AXIS-2 ********************* -->
  <link name="axis2">
  	<visual>
	  <origin xyz="-0.5 0 0.05" rpy="0 0 0" />
  	  <geometry>
        <box size="0.1 0.1 1.0"/>
  	  </geometry>
  	  <material name="blue">
  		<color rgba="0 0 1 1" />
  	  </material>	  
  	</visual>

	<inertial>
	  <mass value="0.1405"/>
	  <inertia
		  ixx="0.011825416666666668" ixy="0.0" ixz="0.0"
		  iyy="0.00023416666666666673" iyz="0.0"
		  izz="0.011825416666666668"/>
	</inertial>

	<collision>
	  <origin xyz="-0.5 0 0.06" rpy="0 0 0" />
	  <geometry>
      <box size="0.1 0.1 1.0"/>
	  </geometry>
	</collision>
  </link>

  <!-- ********************* AXIS-3 ********************* -->
  <link name="axis3">
  	<visual>
	  <origin xyz="-0.5 0 -0.05" rpy="0 0 0" />
  	  <geometry>
        <box size="0.1 0.1 1.0"/>
  	  </geometry>
  	  <material name="red">
  		<color rgba="1 0 0 1" />
  	  </material>	  
  	</visual>

	<inertial>
	  <mass value="0.1405"/>
	  <inertia
		  ixx="0.011825416666666668" ixy="0.0" ixz="0.0"
		  iyy="0.00023416666666666673" iyz="0.0"
		  izz="0.011825416666666668"/>
	</inertial>

	<collision>
	  <origin xyz="-0.5 0 -0.06" rpy="0 0 0" />
	  <geometry>
      <box size="0.1 0.1 1.0"/>
	  </geometry>
	</collision>
  </link>

 <!-- ********************* AXIS-4 ********************* -->
  <link name="axis4">
  	<visual>
      <origin xyz="0 0 0" rpy="0 0 0" />
      <geometry>
        <cylinder radius="0.05" length="0.05" />
      </geometry>
      <material name="greyGreen">
      <color rgba="0 0.5 0 0.5" />
      </material>	  
  	</visual>

	<inertial>
	  <mass value="0.028100"/>
	  <inertia
		  ixx="0.00011708" ixy="0.0" ixz="0.0"
		  iyy="0.000046833" iyz="0.0"
		  izz="0.00011708"/>
	</inertial>

	<collision>
	  <origin xyz="0 0 0" rpy="0 0 0" />
    <geometry>
      <cylinder radius="0.05" length="0.05" />
    </geometry>
	</collision>
  </link>

 <!-- ********************* AXIS-5 ********************* -->
  <link name="axis5">
  	<visual>
      <origin xyz="0 0 0" rpy="0 0 0" />
      <geometry>
        <cylinder radius="0.05" length="0.05" />
      </geometry>
      <material name="darkGreen">
      <color rgba="0 0.2 0 0.2" />
      </material>	  
  	</visual>

	<inertial>
	  <mass value="0.028100"/>
	  <inertia
		  ixx="0.00011708" ixy="0.0" ixz="0.0"
		  iyy="0.000046833" iyz="0.0"
		  izz="0.00011708"/>
	</inertial>

	<collision>
	  <origin xyz="0 0 0" rpy="0 0 0" />
    <geometry>
      <cylinder radius="0.05" length="0.05" />
    </geometry>
	</collision>
  </link>

 <!-- ********************* AXIS-6 ********************* -->
  <link name="axis6">
  	<visual>
      <origin xyz="0 0 0" rpy="0 0 0" />
      <geometry>
        <cylinder radius="0.05" length="0.05" />
      </geometry>
      <material name="grey">
      <color rgba="0 0.5 0.5 0.5" />
      </material>	  
  	</visual>

	<inertial>
	  <mass value="0.028100"/>
	  <inertia
		  ixx="0.00011708" ixy="0.0" ixz="0.0"
		  iyy="0.000046833" iyz="0.0"
		  izz="0.00011708"/>
	</inertial>

	<collision>
	  <origin xyz="0 0 0" rpy="0 0 0" />
    <geometry>
      <cylinder radius="0.05" length="0.05" />
    </geometry>
	</collision>
  </link>

 <!-- ********************* FLANGE ********************* -->
  <link name="flange">
  	<visual>
      <origin xyz="0 0 0" rpy="0 0 0" />
      <geometry>
        <box size="0.1 0.1 0.05"/>
        <!--cylinder radius="0.055" length="0.05" /-->
      </geometry>
      <material name="black">
      <color rgba="0 0 0 0" />
      </material>	  
  	</visual>

	<inertial>
	  <mass value="0.028100"/>
	  <inertia
		  ixx="0.00011708" ixy="0.0" ixz="0.0"
		  iyy="0.000046833" iyz="0.0"
		  izz="0.00011708"/>
	</inertial>

	<collision>
	  <origin xyz="0 0 0" rpy="0 0 0" />
    <geometry>
      <cylinder radius="0.05" length="0.05" />
    </geometry>
	</collision>
  </link>

  <!-- ********************* JOINTS ********************* -->

  <joint name="world_joint"  type="fixed">
  	<origin xyz="0 0 0" rpy="0 0 0" />
    <parent link="world"/>
    <child link="axis1"/>
  </joint>

  <joint name="joint1" type="prismatic">
    <limit lower="-0.45" upper="0.45" effort="12" velocity="2.443"/>
  	<parent link="axis1" />
  	<child link="axis2" />
    <origin xyz="0.5 0 0" rpy="0 1.570796 0"/>
    <axis xyz="-1 0 0" />
  </joint>

	<joint name="joint_2" type="prismatic">
    <limit lower="-0.4" upper="0.5" effort="12" velocity="2.443"/>
  	<parent link="axis2" />
  	<child link="axis3" />
    <origin xyz="0 0.5 0.0" rpy="1.570796 0 0"/>
    <axis xyz="0 1 0" />
  </joint>

	<joint name="joint_3" type="prismatic">
    <limit lower="-0.3" upper="0.5" effort="12" velocity="2.443"/>
  	<parent link="axis3" />
  	<child link="axis4" />
    <origin xyz="-0.425 0 0" rpy="0 1.570796 0"/>
    <axis xyz="1 0 0"/>
  </joint>

  <joint name="joint_4" type="revolute">
    <limit lower="-3.14" upper="3.14" effort="12" velocity="2.443"/>
  	<parent link="axis4" />
  	<child link="axis5" />
    <origin xyz="0 0 0.075" rpy="0 1.570796 1.570796"/>
    <axis xyz="0 1 0" />
  </joint>

  <joint name="joint_5" type="revolute">
    <limit lower="-3.14" upper="3.14" effort="12" velocity="2.443"/>
  	<parent link="axis5" />
  	<child link="axis6" />
    <origin xyz="-0.075 0 0" rpy="0 1.570796 0"/>
    <axis xyz="1 0 0" />
  </joint>

  <joint name="joint_6" type="revolute">
    <limit lower="-3.14" upper="3.14" effort="12" velocity="2.443"/>
  	<parent link="axis6" />
  	<child link="flange" />
    <origin xyz="0 0 -0.05" rpy="0 0 0"/>
    <axis xyz="0 0 1" />
  </joint>

  <!-- ************* ACTUATOR TRANSMISSIONS ************* -->

	<transmission name="joint1_trans">
		<type>transmission_interface/SimpleTransmission</type>
		<joint name="joint1">
			<hardwareInterface>hardware_interface/EffortJointInterface</hardwareInterface>
		</joint>
		<actuator name="joint1_motor">
			<mechanicalReduction>50</mechanicalReduction>
		</actuator>
	</transmission>

  <transmission name="joint_2_trans">
    <type>transmission_interface/SimpleTransmission</type>
    <joint name="joint_2">
      <hardwareInterface>hardware_interface/EffortJointInterface</hardwareInterface>
    </joint>
    <actuator name="joint_2_motor">
      <mechanicalReduction>50</mechanicalReduction>
    </actuator>
  </transmission>

  <transmission name="joint_3_trans">
    <type>transmission_interface/SimpleTransmission</type>
    <joint name="joint_3">
      <hardwareInterface>hardware_interface/EffortJointInterface</hardwareInterface>
    </joint>
    <actuator name="joint_3_motor">
      <mechanicalReduction>50</mechanicalReduction>
    </actuator>
  </transmission>

  <!-- ********************* GAZEBO ********************* -->



</robot>